Workbook

Sheet Resumo
B2: RESUMO ANUAL — CUSTOS DA CASA 2026
B5: Mês | C5: Entradas | D5: Saídas | E5: Saldo | F5: Saldo Acumulado | G5: Fatura Cartão
B6: Janeiro | C6: =IFERROR(Janeiro!C4,0) -> 0 | D6: =IFERROR(Janeiro!C5,0) -> 0 | E6: =C6-D6 -> 0 | F6: =SUM($E$6:E6) -> 0 | G6: =IFERROR('Janeiro-Cartão'!D4,0) -> 0
B7: Fevereiro | C7: =IFERROR(Fevereiro!C4,0) -> 0 | D7: =IFERROR(Fevereiro!C5,0) -> 0 | E7: =C7-D7 -> 0 | F7: =SUM($E$6:E7) -> 0 | G7: =IFERROR('Fevereiro-Cartão'!D4,0) -> 0
B8: Março | C8: =IFERROR(Março!C4,0) -> 0 | D8: =IFERROR(Março!C5,0) -> 0 | E8: =C8-D8 -> 0 | F8: =SUM($E$6:E8) -> 0 | G8: =IFERROR('Março-Cartão'!D4,0) -> 0
B9: Abril | C9: =IFERROR(Abril!C4,0) -> 0 | D9: =IFERROR(Abril!C5,0) -> 0 | E9: =C9-D9 -> 0 | F9: =SUM($E$6:E9) -> 0 | G9: =IFERROR('Abril-Cartão'!D4,0) -> 0
B10: Maio | C10: =IFERROR(Maio!C4,0) -> 0 | D10: =IFERROR(Maio!C5,0) -> 0 | E10: =C10-D10 -> 0 | F10: =SUM($E$6:E10) -> 0 | G10: =IFERROR('Maio-Cartão'!D4,0) -> 0
B11: Junho | C11: =IFERROR(Junho!C4,0) -> 0 | D11: =IFERROR(Junho!C5,0) -> 0 | E11: =C11-D11 -> 0 | F11: =SUM($E$6:E11) -> 0 | G11: =IFERROR('Junho-Cartão'!D4,0) -> 0
B12: Julho | C12: =IFERROR(Julho!C4,0) -> 10950.24 | D12: =IFERROR(Julho!C5,0) -> 9298.474 | E12: =C12-D12 -> 1651.766 | F12: =SUM($E$6:E12) -> 1651.766 | G12: =IFERROR('Julho-Cartão'!D4,0) -> 4823.58
B13: Agosto | C13: =IFERROR(Agosto!C4,0) -> 17241.54 | D13: =IFERROR(Agosto!C5,0) -> 20477.424 | E13: =C13-D13 -> -3235.884 | F13: =SUM($E$6:E13) -> -1584.118 | G13: =IFERROR('Agosto-Cartão'!D4,0) -> 3549.19
B14: Setembro | C14: =IFERROR(Setembro!C4,0) -> 0 | D14: =IFERROR(Setembro!C5,0) -> 0 | E14: =C14-D14 -> 0 | F14: =SUM($E$6:E14) -> -1584.118 | G14: =IFERROR('Setembro-Cartão'!D4,0) -> 0
B15: Outubro | C15: =IFERROR(Outubro!C4,0) -> 0 | D15: =IFERROR(Outubro!C5,0) -> 0 | E15: =C15-D15 -> 0 | F15: =SUM($E$6:E15) -> -1584.118 | G15: =IFERROR('Outubro-Cartão'!D4,0) -> 0
B16: Novembro | C16: =IFERROR(Novembro!C4,0) -> 0 | D16: =IFERROR(Novembro!C5,0) -> 0 | E16: =C16-D16 -> 0 | F16: =SUM($E$6:E16) -> -1584.118 | G16: =IFERROR('Novembro-Cartão'!D4,0) -> 0
B17: Dezembro | C17: =IFERROR(Dezembro!C4,0) -> 0 | D17: =IFERROR(Dezembro!C5,0) -> 0 | E17: =C17-D17 -> 0 | F17: =SUM($E$6:E17) -> -1584.118 | G17: =IFERROR('Dezembro-Cartão'!D4,0) -> 0
B18: TOTAL ANO | C18: =SUM(C6:C17) -> 28191.78 | D18: =SUM(D6:D17) -> 29775.898 | E18: =SUM(E6:E17) -> -1584.118 | F18: =F17 -> -1584.118 | G18: =SUM(G6:G17) -> 8372.77
B21: COMO USAR:
B22: 1. Clique com o botão direito na aba "Mês" → Mover ou copiar → marque "Criar uma cópia".
B23: 2. Renomeie a cópia com o nome do mês (ex.: "Janeiro") e digite o mesmo nome na célula C2 dela.
B24: 3. Faça o mesmo com a aba "Mês-Cartão" (ex.: "Janeiro-Cartão").
B25: 4. O Resumo puxa os valores automaticamente pelo nome da aba. Meses ainda não criados aparecem como "-".

Sheet Janeiro
B1: CONTROLE MENSAL
B2: Mês: | C2: Janeiro | D2: ← digite aqui o mesmo nome da aba (ex.: Janeiro)
B4: Total de Entradas | C4: =C21 -> 0 | G4: Total Pago | H4: =SUMIF($I$11:$I$60,"Pago",$H$11:$H$60) -> 0
B5: Total de Saídas | C5: =L20 -> 0 | G5: Total a Pagar | H5: =SUMIF($I$11:$I$60,"Não pago",$H$11:$H$60) -> 0
B6: Saldo do Mês | C6: =C4-C5 -> 0
B9: ENTRADAS | E9: SAÍDAS (exceto cartão de crédito) | K9: RESUMO POR CATEGORIA
B10: Descrição | C10: Valor | E10: Data | F10: Descrição | G10: Categoria | H10: Valor | I10: Pago? | K10: Categoria | L10: Total | M10: %
K11: Moradia (aluguel/condomínio) | L11: =SUMIF($G$11:$G$60,K11,$H$11:$H$60) -> 0 | M11: =IF($L$20=0,0,L11/$L$20) -> 0
K12: Contas (luz/água/internet) | L12: =SUMIF($G$11:$G$60,K12,$H$11:$H$60) -> 0 | M12: =IF($L$20=0,0,L12/$L$20) -> 0
K13: Mercado | L13: =SUMIF($G$11:$G$60,K13,$H$11:$H$60) -> 0 | M13: =IF($L$20=0,0,L13/$L$20) -> 0
K14: Transporte | L14: =SUMIF($G$11:$G$60,K14,$H$11:$H$60) -> 0 | M14: =IF($L$20=0,0,L14/$L$20) -> 0
K15: Saúde | L15: =SUMIF($G$11:$G$60,K15,$H$11:$H$60) -> 0 | M15: =IF($L$20=0,0,L15/$L$20) -> 0
K16: Educação | L16: =SUMIF($G$11:$G$60,K16,$H$11:$H$60) -> 0 | M16: =IF($L$20=0,0,L16/$L$20) -> 0
K17: Lazer | L17: =SUMIF($G$11:$G$60,K17,$H$11:$H$60) -> 0 | M17: =IF($L$20=0,0,L17/$L$20) -> 0
K18: Outros | L18: =SUMIF($G$11:$G$60,K18,$H$11:$H$60) -> 0 | M18: =IF($L$20=0,0,L18/$L$20) -> 0
K19: Cartão de Crédito | L19: =IFERROR('Janeiro-Cartão'!D4,0) -> 0 | M19: =IF($L$20=0,0,L19/$L$20) -> 0
K20: Total | L20: =SUM(L11:L19) -> 0 | M20: =IF(L20=0,0,L20/L20) -> 0
B21: Total | C21: =SUM(C11:C20) -> 0
K22: O Cartão de Crédito vem automático da aba "Mês-Cartão" — não lance a fatura nas Saídas.
E61: Total lançado | H61: =SUM(H11:H60) -> 0

Sheet Janeiro-Cartão
B1: ESTUDO DA FATURA DO CARTÃO DE CRÉDITO
C2: Mês: | D2: Janeiro | E2: ← digite o mesmo nome da aba do mês (ex.: Janeiro)
I3: NU RICARDO | J3: =SUMIFS(G:G,B:B,I3) -> 0
C4: Total da Fatura | D4: =G110 -> 0 | I4: VISA RICARDO | J4: =SUMIFS(G:G,B:B,I4) -> 0
I5: NU HELENA | J5: =SUMIFS(G:G,B:B,I5) -> 0
I6: TOTAL | J6: =SUM(J3:J5) -> 0
B8: LANÇAMENTOS DA FATURA | I8: ONDE ESTOU GASTANDO
B9: CARTÃO | C9: Data | D9: Descrição | E9: Parcela | F9: Categoria | G9: Valor | I9: Categoria | J9: Total | K9: %
I10: Mercado | J10: =SUMIF($F$10:$F$109,I10,$G$10:$G$109) -> 0 | K10: =IF($J$21=0,0,J10/$J$21) -> 0
I11: Restaurantes/Delivery | J11: =SUMIF($F$10:$F$109,I11,$G$10:$G$109) -> 0 | K11: =IF($J$21=0,0,J11/$J$21) -> 0
I12: Transporte/Combustível | J12: =SUMIF($F$10:$F$109,I12,$G$10:$G$109) -> 0 | K12: =IF($J$21=0,0,J12/$J$21) -> 0
I13: Assinaturas/Streaming | J13: =SUMIF($F$10:$F$109,I13,$G$10:$G$109) -> 0 | K13: =IF($J$21=0,0,J13/$J$21) -> 0
I14: Vestuário | J14: =SUMIF($F$10:$F$109,I14,$G$10:$G$109) -> 0 | K14: =IF($J$21=0,0,J14/$J$21) -> 0
I15: Saúde/Farmácia | J15: =SUMIF($F$10:$F$109,I15,$G$10:$G$109) -> 0 | K15: =IF($J$21=0,0,J15/$J$21) -> 0
I16: Casa | J16: =SUMIF($F$10:$F$109,I16,$G$10:$G$109) -> 0 | K16: =IF($J$21=0,0,J16/$J$21) -> 0
I17: Lazer | J17: =SUMIF($F$10:$F$109,I17,$G$10:$G$109) -> 0 | K17: =IF($J$21=0,0,J17/$J$21) -> 0
I18: Viagem | J18: =SUMIF($F$10:$F$109,I18,$G$10:$G$109) -> 0 | K18: =IF($J$21=0,0,J18/$J$21) -> 0
I19: Educação | J19: =SUMIF($F$10:$F$109,I19,$G$10:$G$109) -> 0 | K19: =IF($J$21=0,0,J19/$J$21) -> 0
I20: Outros | J20: =SUMIF($F$10:$F$109,I20,$G$10:$G$109) -> 0 | K20: =IF($J$21=0,0,J20/$J$21) -> 0
I21: Total | J21: =SUM(J10:J20) -> 0 | K21: =IF(J21=0,0,J21/J21) -> 0
B110: Total | C110: Total | G110: =SUM(G10:G109) -> 0

Sheet Fevereiro
B1: CONTROLE MENSAL
B2: Mês: | C2: Fevereiro | D2: ← digite aqui o mesmo nome da aba (ex.: Janeiro)
B4: Total de Entradas | C4: =C21 -> 0 | G4: Total Pago | H4: =SUMIF($I$11:$I$60,"Pago",$H$11:$H$60) -> 0
B5: Total de Saídas | C5: =L20 -> 0 | G5: Total a Pagar | H5: =SUMIF($I$11:$I$60,"Não pago",$H$11:$H$60) -> 0
B6: Saldo do Mês | C6: =C4-C5 -> 0
B9: ENTRADAS | E9: SAÍDAS (exceto cartão de crédito) | K9: RESUMO POR CATEGORIA
B10: Descrição | C10: Valor | E10: Data | F10: Descrição | G10: Categoria | H10: Valor | I10: Pago? | K10: Categoria | L10: Total | M10: %
K11: Moradia (aluguel/condomínio) | L11: =SUMIF($G$11:$G$60,K11,$H$11:$H$60) -> 0 | M11: =IF($L$20=0,0,L11/$L$20) -> 0
K12: Contas (luz/água/internet) | L12: =SUMIF($G$11:$G$60,K12,$H$11:$H$60) -> 0 | M12: =IF($L$20=0,0,L12/$L$20) -> 0
K13: Mercado | L13: =SUMIF($G$11:$G$60,K13,$H$11:$H$60) -> 0 | M13: =IF($L$20=0,0,L13/$L$20) -> 0
K14: Transporte | L14: =SUMIF($G$11:$G$60,K14,$H$11:$H$60) -> 0 | M14: =IF($L$20=0,0,L14/$L$20) -> 0
K15: Saúde | L15: =SUMIF($G$11:$G$60,K15,$H$11:$H$60) -> 0 | M15: =IF($L$20=0,0,L15/$L$20) -> 0
K16: Educação | L16: =SUMIF($G$11:$G$60,K16,$H$11:$H$60) -> 0 | M16: =IF($L$20=0,0,L16/$L$20) -> 0
K17: Lazer | L17: =SUMIF($G$11:$G$60,K17,$H$11:$H$60) -> 0 | M17: =IF($L$20=0,0,L17/$L$20) -> 0
K18: Outros | L18: =SUMIF($G$11:$G$60,K18,$H$11:$H$60) -> 0 | M18: =IF($L$20=0,0,L18/$L$20) -> 0
K19: Cartão de Crédito | L19: =IFERROR('Fevereiro-Cartão'!D4,0) -> 0 | M19: =IF($L$20=0,0,L19/$L$20) -> 0
K20: Total | L20: =SUM(L11:L19) -> 0 | M20: =IF(L20=0,0,L20/L20) -> 0
B21: Total | C21: =SUM(C11:C20) -> 0
K22: O Cartão de Crédito vem automático da aba "Mês-Cartão" — não lance a fatura nas Saídas.
E61: Total lançado | H61: =SUM(H11:H60) -> 0

Sheet Fevereiro-Cartão
B1: ESTUDO DA FATURA DO CARTÃO DE CRÉDITO
C2: Mês: | D2: Fevereiro | E2: ← digite o mesmo nome da aba do mês (ex.: Janeiro)
I3: NU RICARDO | J3: =SUMIFS(G:G,B:B,I3) -> 0
C4: Total da Fatura | D4: =G110 -> 0 | I4: VISA RICARDO | J4: =SUMIFS(G:G,B:B,I4) -> 0
I5: NU HELENA | J5: =SUMIFS(G:G,B:B,I5) -> 0
I6: TOTAL | J6: =SUM(J3:J5) -> 0
B8: LANÇAMENTOS DA FATURA | I8: ONDE ESTOU GASTANDO
B9: CARTÃO | C9: Data | D9: Descrição | E9: Parcela | F9: Categoria | G9: Valor | I9: Categoria | J9: Total | K9: %
I10: Mercado | J10: =SUMIF($F$10:$F$109,I10,$G$10:$G$109) -> 0 | K10: =IF($J$21=0,0,J10/$J$21) -> 0
I11: Restaurantes/Delivery | J11: =SUMIF($F$10:$F$109,I11,$G$10:$G$109) -> 0 | K11: =IF($J$21=0,0,J11/$J$21) -> 0
I12: Transporte/Combustível | J12: =SUMIF($F$10:$F$109,I12,$G$10:$G$109) -> 0 | K12: =IF($J$21=0,0,J12/$J$21) -> 0
I13: Assinaturas/Streaming | J13: =SUMIF($F$10:$F$109,I13,$G$10:$G$109) -> 0 | K13: =IF($J$21=0,0,J13/$J$21) -> 0
I14: Vestuário | J14: =SUMIF($F$10:$F$109,I14,$G$10:$G$109) -> 0 | K14: =IF($J$21=0,0,J14/$J$21) -> 0
I15: Saúde/Farmácia | J15: =SUMIF($F$10:$F$109,I15,$G$10:$G$109) -> 0 | K15: =IF($J$21=0,0,J15/$J$21) -> 0
I16: Casa | J16: =SUMIF($F$10:$F$109,I16,$G$10:$G$109) -> 0 | K16: =IF($J$21=0,0,J16/$J$21) -> 0
I17: Lazer | J17: =SUMIF($F$10:$F$109,I17,$G$10:$G$109) -> 0 | K17: =IF($J$21=0,0,J17/$J$21) -> 0
I18: Viagem | J18: =SUMIF($F$10:$F$109,I18,$G$10:$G$109) -> 0 | K18: =IF($J$21=0,0,J18/$J$21) -> 0
I19: Educação | J19: =SUMIF($F$10:$F$109,I19,$G$10:$G$109) -> 0 | K19: =IF($J$21=0,0,J19/$J$21) -> 0
I20: Outros | J20: =SUMIF($F$10:$F$109,I20,$G$10:$G$109) -> 0 | K20: =IF($J$21=0,0,J20/$J$21) -> 0
I21: Total | J21: =SUM(J10:J20) -> 0 | K21: =IF(J21=0,0,J21/J21) -> 0
B110: Total | C110: Total | G110: =SUM(G10:G109) -> 0

Sheet Março
B1: CONTROLE MENSAL
B2: Mês: | C2: Março | D2: ← digite aqui o mesmo nome da aba (ex.: Janeiro)
B4: Total de Entradas | C4: =C21 -> 0 | G4: Total Pago | H4: =SUMIF($I$11:$I$60,"Pago",$H$11:$H$60) -> 0
B5: Total de Saídas | C5: =L20 -> 0 | G5: Total a Pagar | H5: =SUMIF($I$11:$I$60,"Não pago",$H$11:$H$60) -> 0
B6: Saldo do Mês | C6: =C4-C5 -> 0
B9: ENTRADAS | E9: SAÍDAS (exceto cartão de crédito) | K9: RESUMO POR CATEGORIA
B10: Descrição | C10: Valor | E10: Data | F10: Descrição | G10: Categoria | H10: Valor | I10: Pago? | K10: Categoria | L10: Total | M10: %
K11: Moradia (aluguel/condomínio) | L11: =SUMIF($G$11:$G$60,K11,$H$11:$H$60) -> 0 | M11: =IF($L$20=0,0,L11/$L$20) -> 0
K12: Contas (luz/água/internet) | L12: =SUMIF($G$11:$G$60,K12,$H$11:$H$60) -> 0 | M12: =IF($L$20=0,0,L12/$L$20) -> 0
K13: Mercado | L13: =SUMIF($G$11:$G$60,K13,$H$11:$H$60) -> 0 | M13: =IF($L$20=0,0,L13/$L$20) -> 0
K14: Transporte | L14: =SUMIF($G$11:$G$60,K14,$H$11:$H$60) -> 0 | M14: =IF($L$20=0,0,L14/$L$20) -> 0
K15: Saúde | L15: =SUMIF($G$11:$G$60,K15,$H$11:$H$60) -> 0 | M15: =IF($L$20=0,0,L15/$L$20) -> 0
K16: Educação | L16: =SUMIF($G$11:$G$60,K16,$H$11:$H$60) -> 0 | M16: =IF($L$20=0,0,L16/$L$20) -> 0
K17: Lazer | L17: =SUMIF($G$11:$G$60,K17,$H$11:$H$60) -> 0 | M17: =IF($L$20=0,0,L17/$L$20) -> 0
K18: Outros | L18: =SUMIF($G$11:$G$60,K18,$H$11:$H$60) -> 0 | M18: =IF($L$20=0,0,L18/$L$20) -> 0
K19: Cartão de Crédito | L19: =IFERROR('Março-Cartão'!D4,0) -> 0 | M19: =IF($L$20=0,0,L19/$L$20) -> 0
K20: Total | L20: =SUM(L11:L19) -> 0 | M20: =IF(L20=0,0,L20/L20) -> 0
B21: Total | C21: =SUM(C11:C20) -> 0
K22: O Cartão de Crédito vem automático da aba "Mês-Cartão" — não lance a fatura nas Saídas.
E61: Total lançado | H61: =SUM(H11:H60) -> 0

Sheet Março-Cartão
B1: ESTUDO DA FATURA DO CARTÃO DE CRÉDITO
C2: Mês: | D2: Março | E2: ← digite o mesmo nome da aba do mês (ex.: Janeiro)
I3: NU RICARDO | J3: =SUMIFS(G:G,B:B,I3) -> 0
C4: Total da Fatura | D4: =G110 -> 0 | I4: VISA RICARDO | J4: =SUMIFS(G:G,B:B,I4) -> 0
I5: NU HELENA | J5: =SUMIFS(G:G,B:B,I5) -> 0
I6: TOTAL | J6: =SUM(J3:J5) -> 0
B8: LANÇAMENTOS DA FATURA | I8: ONDE ESTOU GASTANDO
B9: CARTÃO | C9: Data | D9: Descrição | E9: Parcela | F9: Categoria | G9: Valor | I9: Categoria | J9: Total | K9: %
I10: Mercado | J10: =SUMIF($F$10:$F$109,I10,$G$10:$G$109) -> 0 | K10: =IF($J$21=0,0,J10/$J$21) -> 0
I11: Restaurantes/Delivery | J11: =SUMIF($F$10:$F$109,I11,$G$10:$G$109) -> 0 | K11: =IF($J$21=0,0,J11/$J$21) -> 0
I12: Transporte/Combustível | J12: =SUMIF($F$10:$F$109,I12,$G$10:$G$109) -> 0 | K12: =IF($J$21=0,0,J12/$J$21) -> 0
I13: Assinaturas/Streaming | J13: =SUMIF($F$10:$F$109,I13,$G$10:$G$109) -> 0 | K13: =IF($J$21=0,0,J13/$J$21) -> 0
I14: Vestuário | J14: =SUMIF($F$10:$F$109,I14,$G$10:$G$109) -> 0 | K14: =IF($J$21=0,0,J14/$J$21) -> 0
I15: Saúde/Farmácia | J15: =SUMIF($F$10:$F$109,I15,$G$10:$G$109) -> 0 | K15: =IF($J$21=0,0,J15/$J$21) -> 0
I16: Casa | J16: =SUMIF($F$10:$F$109,I16,$G$10:$G$109) -> 0 | K16: =IF($J$21=0,0,J16/$J$21) -> 0
I17: Lazer | J17: =SUMIF($F$10:$F$109,I17,$G$10:$G$109) -> 0 | K17: =IF($J$21=0,0,J17/$J$21) -> 0
I18: Viagem | J18: =SUMIF($F$10:$F$109,I18,$G$10:$G$109) -> 0 | K18: =IF($J$21=0,0,J18/$J$21) -> 0
I19: Educação | J19: =SUMIF($F$10:$F$109,I19,$G$10:$G$109) -> 0 | K19: =IF($J$21=0,0,J19/$J$21) -> 0
I20: Outros | J20: =SUMIF($F$10:$F$109,I20,$G$10:$G$109) -> 0 | K20: =IF($J$21=0,0,J20/$J$21) -> 0
I21: Total | J21: =SUM(J10:J20) -> 0 | K21: =IF(J21=0,0,J21/J21) -> 0
B110: Total | C110: Total | G110: =SUM(G10:G109) -> 0

Sheet Abril
B1: CONTROLE MENSAL
B2: Mês: | C2: Abril | D2: ← digite aqui o mesmo nome da aba (ex.: Janeiro)
B4: Total de Entradas | C4: =C21 -> 0 | G4: Total Pago | H4: =SUMIF($I$11:$I$60,"Pago",$H$11:$H$60) -> 0
B5: Total de Saídas | C5: =L20 -> 0 | G5: Total a Pagar | H5: =SUMIF($I$11:$I$60,"Não pago",$H$11:$H$60) -> 0
B6: Saldo do Mês | C6: =C4-C5 -> 0
B9: ENTRADAS | E9: SAÍDAS (exceto cartão de crédito) | K9: RESUMO POR CATEGORIA
B10: Descrição | C10: Valor | E10: Data | F10: Descrição | G10: Categoria | H10: Valor | I10: Pago? | K10: Categoria | L10: Total | M10: %
K11: Moradia (aluguel/condomínio) | L11: =SUMIF($G$11:$G$60,K11,$H$11:$H$60) -> 0 | M11: =IF($L$20=0,0,L11/$L$20) -> 0
K12: Contas (luz/água/internet) | L12: =SUMIF($G$11:$G$60,K12,$H$11:$H$60) -> 0 | M12: =IF($L$20=0,0,L12/$L$20) -> 0
K13: Mercado | L13: =SUMIF($G$11:$G$60,K13,$H$11:$H$60) -> 0 | M13: =IF($L$20=0,0,L13/$L$20) -> 0
K14: Transporte | L14: =SUMIF($G$11:$G$60,K14,$H$11:$H$60) -> 0 | M14: =IF($L$20=0,0,L14/$L$20) -> 0
K15: Saúde | L15: =SUMIF($G$11:$G$60,K15,$H$11:$H$60) -> 0 | M15: =IF($L$20=0,0,L15/$L$20) -> 0
K16: Educação | L16: =SUMIF($G$11:$G$60,K16,$H$11:$H$60) -> 0 | M16: =IF($L$20=0,0,L16/$L$20) -> 0
K17: Lazer | L17: =SUMIF($G$11:$G$60,K17,$H$11:$H$60) -> 0 | M17: =IF($L$20=0,0,L17/$L$20) -> 0
K18: Outros | L18: =SUMIF($G$11:$G$60,K18,$H$11:$H$60) -> 0 | M18: =IF($L$20=0,0,L18/$L$20) -> 0
K19: Cartão de Crédito | L19: =IFERROR('Abril-Cartão'!D4,0) -> 0 | M19: =IF($L$20=0,0,L19/$L$20) -> 0
K20: Total | L20: =SUM(L11:L19) -> 0 | M20: =IF(L20=0,0,L20/L20) -> 0
B21: Total | C21: =SUM(C11:C20) -> 0
K22: O Cartão de Crédito vem automático da aba "Mês-Cartão" — não lance a fatura nas Saídas.
E61: Total lançado | H61: =SUM(H11:H60) -> 0

Sheet Abril-Cartão
B1: ESTUDO DA FATURA DO CARTÃO DE CRÉDITO
C2: Mês: | D2: Abril | E2: ← digite o mesmo nome da aba do mês (ex.: Janeiro)
I3: NU RICARDO | J3: =SUMIFS(G:G,B:B,I3) -> 0
C4: Total da Fatura | D4: =G110 -> 0 | I4: VISA RICARDO | J4: =SUMIFS(G:G,B:B,I4) -> 0
I5: NU HELENA | J5: =SUMIFS(G:G,B:B,I5) -> 0
I6: TOTAL | J6: =SUM(J3:J5) -> 0
B8: LANÇAMENTOS DA FATURA | I8: ONDE ESTOU GASTANDO
B9: CARTÃO | C9: Data | D9: Descrição | E9: Parcela | F9: Categoria | G9: Valor | I9: Categoria | J9: Total | K9: %
I10: Mercado | J10: =SUMIF($F$10:$F$109,I10,$G$10:$G$109) -> 0 | K10: =IF($J$21=0,0,J10/$J$21) -> 0
I11: Restaurantes/Delivery | J11: =SUMIF($F$10:$F$109,I11,$G$10:$G$109) -> 0 | K11: =IF($J$21=0,0,J11/$J$21) -> 0
I12: Transporte/Combustível | J12: =SUMIF($F$10:$F$109,I12,$G$10:$G$109) -> 0 | K12: =IF($J$21=0,0,J12/$J$21) -> 0
I13: Assinaturas/Streaming | J13: =SUMIF($F$10:$F$109,I13,$G$10:$G$109) -> 0 | K13: =IF($J$21=0,0,J13/$J$21) -> 0
I14: Vestuário | J14: =SUMIF($F$10:$F$109,I14,$G$10:$G$109) -> 0 | K14: =IF($J$21=0,0,J14/$J$21) -> 0
I15: Saúde/Farmácia | J15: =SUMIF($F$10:$F$109,I15,$G$10:$G$109) -> 0 | K15: =IF($J$21=0,0,J15/$J$21) -> 0
I16: Casa | J16: =SUMIF($F$10:$F$109,I16,$G$10:$G$109) -> 0 | K16: =IF($J$21=0,0,J16/$J$21) -> 0
I17: Lazer | J17: =SUMIF($F$10:$F$109,I17,$G$10:$G$109) -> 0 | K17: =IF($J$21=0,0,J17/$J$21) -> 0
I18: Viagem | J18: =SUMIF($F$10:$F$109,I18,$G$10:$G$109) -> 0 | K18: =IF($J$21=0,0,J18/$J$21) -> 0
I19: Educação | J19: =SUMIF($F$10:$F$109,I19,$G$10:$G$109) -> 0 | K19: =IF($J$21=0,0,J19/$J$21) -> 0
I20: Outros | J20: =SUMIF($F$10:$F$109,I20,$G$10:$G$109) -> 0 | K20: =IF($J$21=0,0,J20/$J$21) -> 0
I21: Total | J21: =SUM(J10:J20) -> 0 | K21: =IF(J21=0,0,J21/J21) -> 0
B110: Total | C110: Total | G110: =SUM(G10:G109) -> 0

Sheet Maio
B1: CONTROLE MENSAL
B2: Mês: | C2: Maio | D2: ← digite aqui o mesmo nome da aba (ex.: Janeiro)
B4: Total de Entradas | C4: =C21 -> 0 | G4: Total Pago | H4: =SUMIF($I$11:$I$60,"Pago",$H$11:$H$60) -> 0
B5: Total de Saídas | C5: =L20 -> 0 | G5: Total a Pagar | H5: =SUMIF($I$11:$I$60,"Não pago",$H$11:$H$60) -> 0
B6: Saldo do Mês | C6: =C4-C5 -> 0
B9: ENTRADAS | E9: SAÍDAS (exceto cartão de crédito) | K9: RESUMO POR CATEGORIA
B10: Descrição | C10: Valor | E10: Data | F10: Descrição | G10: Categoria | H10: Valor | I10: Pago? | K10: Categoria | L10: Total | M10: %
K11: Moradia (aluguel/condomínio) | L11: =SUMIF($G$11:$G$60,K11,$H$11:$H$60) -> 0 | M11: =IF($L$20=0,0,L11/$L$20) -> 0
K12: Contas (luz/água/internet) | L12: =SUMIF($G$11:$G$60,K12,$H$11:$H$60) -> 0 | M12: =IF($L$20=0,0,L12/$L$20) -> 0
K13: Mercado | L13: =SUMIF($G$11:$G$60,K13,$H$11:$H$60) -> 0 | M13: =IF($L$20=0,0,L13/$L$20) -> 0
K14: Transporte | L14: =SUMIF($G$11:$G$60,K14,$H$11:$H$60) -> 0 | M14: =IF($L$20=0,0,L14/$L$20) -> 0
K15: Saúde | L15: =SUMIF($G$11:$G$60,K15,$H$11:$H$60) -> 0 | M15: =IF($L$20=0,0,L15/$L$20) -> 0
K16: Educação | L16: =SUMIF($G$11:$G$60,K16,$H$11:$H$60) -> 0 | M16: =IF($L$20=0,0,L16/$L$20) -> 0
K17: Lazer | L17: =SUMIF($G$11:$G$60,K17,$H$11:$H$60) -> 0 | M17: =IF($L$20=0,0,L17/$L$20) -> 0
K18: Outros | L18: =SUMIF($G$11:$G$60,K18,$H$11:$H$60) -> 0 | M18: =IF($L$20=0,0,L18/$L$20) -> 0
K19: Cartão de Crédito | L19: =IFERROR('Maio-Cartão'!D4,0) -> 0 | M19: =IF($L$20=0,0,L19/$L$20) -> 0
K20: Total | L20: =SUM(L11:L19) -> 0 | M20: =IF(L20=0,0,L20/L20) -> 0
B21: Total | C21: =SUM(C11:C20) -> 0
K22: O Cartão de Crédito vem automático da aba "Mês-Cartão" — não lance a fatura nas Saídas.
E61: Total lançado | H61: =SUM(H11:H60) -> 0

Sheet Maio-Cartão
B1: ESTUDO DA FATURA DO CARTÃO DE CRÉDITO
C2: Mês: | D2: Maio | E2: ← digite o mesmo nome da aba do mês (ex.: Janeiro)
I3: NU RICARDO | J3: =SUMIFS(G:G,B:B,I3) -> 0
C4: Total da Fatura | D4: =G110 -> 0 | I4: VISA RICARDO | J4: =SUMIFS(G:G,B:B,I4) -> 0
I5: NU HELENA | J5: =SUMIFS(G:G,B:B,I5) -> 0
I6: TOTAL | J6: =SUM(J3:J5) -> 0
B8: LANÇAMENTOS DA FATURA | I8: ONDE ESTOU GASTANDO
B9: CARTÃO | C9: Data | D9: Descrição | E9: Parcela | F9: Categoria | G9: Valor | I9: Categoria | J9: Total | K9: %
I10: Mercado | J10: =SUMIF($F$10:$F$109,I10,$G$10:$G$109) -> 0 | K10: =IF($J$21=0,0,J10/$J$21) -> 0
I11: Restaurantes/Delivery | J11: =SUMIF($F$10:$F$109,I11,$G$10:$G$109) -> 0 | K11: =IF($J$21=0,0,J11/$J$21) -> 0
I12: Transporte/Combustível | J12: =SUMIF($F$10:$F$109,I12,$G$10:$G$109) -> 0 | K12: =IF($J$21=0,0,J12/$J$21) -> 0
I13: Assinaturas/Streaming | J13: =SUMIF($F$10:$F$109,I13,$G$10:$G$109) -> 0 | K13: =IF($J$21=0,0,J13/$J$21) -> 0
I14: Vestuário | J14: =SUMIF($F$10:$F$109,I14,$G$10:$G$109) -> 0 | K14: =IF($J$21=0,0,J14/$J$21) -> 0
I15: Saúde/Farmácia | J15: =SUMIF($F$10:$F$109,I15,$G$10:$G$109) -> 0 | K15: =IF($J$21=0,0,J15/$J$21) -> 0
I16: Casa | J16: =SUMIF($F$10:$F$109,I16,$G$10:$G$109) -> 0 | K16: =IF($J$21=0,0,J16/$J$21) -> 0
I17: Lazer | J17: =SUMIF($F$10:$F$109,I17,$G$10:$G$109) -> 0 | K17: =IF($J$21=0,0,J17/$J$21) -> 0
I18: Viagem | J18: =SUMIF($F$10:$F$109,I18,$G$10:$G$109) -> 0 | K18: =IF($J$21=0,0,J18/$J$21) -> 0
I19: Educação | J19: =SUMIF($F$10:$F$109,I19,$G$10:$G$109) -> 0 | K19: =IF($J$21=0,0,J19/$J$21) -> 0
I20: Outros | J20: =SUMIF($F$10:$F$109,I20,$G$10:$G$109) -> 0 | K20: =IF($J$21=0,0,J20/$J$21) -> 0
I21: Total | J21: =SUM(J10:J20) -> 0 | K21: =IF(J21=0,0,J21/J21) -> 0
B110: Total | C110: Total | G110: =SUM(G10:G109) -> 0

Sheet Junho
B1: CONTROLE MENSAL
B2: Mês: | C2: Junho | D2: ← digite aqui o mesmo nome da aba (ex.: Janeiro)
B4: Total de Entradas | C4: =C21 -> 0 | G4: Total Pago | H4: =SUMIF($I$11:$I$60,"Pago",$H$11:$H$60) -> 0
B5: Total de Saídas | C5: =L20 -> 0 | G5: Total a Pagar | H5: =SUMIF($I$11:$I$60,"Não pago",$H$11:$H$60) -> 0
B6: Saldo do Mês | C6: =C4-C5 -> 0
B9: ENTRADAS | E9: SAÍDAS (exceto cartão de crédito) | K9: RESUMO POR CATEGORIA
B10: Descrição | C10: Valor | E10: Data | F10: Descrição | G10: Categoria | H10: Valor | I10: Pago? | K10: Categoria | L10: Total | M10: %
K11: Moradia (aluguel/condomínio) | L11: =SUMIF($G$11:$G$60,K11,$H$11:$H$60) -> 0 | M11: =IF($L$20=0,0,L11/$L$20) -> 0
K12: Contas (luz/água/internet) | L12: =SUMIF($G$11:$G$60,K12,$H$11:$H$60) -> 0 | M12: =IF($L$20=0,0,L12/$L$20) -> 0
K13: Mercado | L13: =SUMIF($G$11:$G$60,K13,$H$11:$H$60) -> 0 | M13: =IF($L$20=0,0,L13/$L$20) -> 0
K14: Transporte | L14: =SUMIF($G$11:$G$60,K14,$H$11:$H$60) -> 0 | M14: =IF($L$20=0,0,L14/$L$20) -> 0
K15: Saúde | L15: =SUMIF($G$11:$G$60,K15,$H$11:$H$60) -> 0 | M15: =IF($L$20=0,0,L15/$L$20) -> 0
K16: Educação | L16: =SUMIF($G$11:$G$60,K16,$H$11:$H$60) -> 0 | M16: =IF($L$20=0,0,L16/$L$20) -> 0
K17: Lazer | L17: =SUMIF($G$11:$G$60,K17,$H$11:$H$60) -> 0 | M17: =IF($L$20=0,0,L17/$L$20) -> 0
K18: Outros | L18: =SUMIF($G$11:$G$60,K18,$H$11:$H$60) -> 0 | M18: =IF($L$20=0,0,L18/$L$20) -> 0
K19: Cartão de Crédito | L19: =IFERROR('Junho-Cartão'!D4,0) -> 0 | M19: =IF($L$20=0,0,L19/$L$20) -> 0
K20: Total | L20: =SUM(L11:L19) -> 0 | M20: =IF(L20=0,0,L20/L20) -> 0
B21: Total | C21: =SUM(C11:C20) -> 0
K22: O Cartão de Crédito vem automático da aba "Mês-Cartão" — não lance a fatura nas Saídas.
E61: Total lançado | H61: =SUM(H11:H60) -> 0

Sheet Junho-Cartão
B1: ESTUDO DA FATURA DO CARTÃO DE CRÉDITO
C2: Mês: | D2: Junho | E2: ← digite o mesmo nome da aba do mês (ex.: Janeiro)
I3: NU RICARDO | J3: =SUMIFS(G:G,B:B,I3) -> 0
C4: Total da Fatura | D4: =G110 -> 0 | I4: VISA RICARDO | J4: =SUMIFS(G:G,B:B,I4) -> 0
I5: NU HELENA | J5: =SUMIFS(G:G,B:B,I5) -> 0
I6: TOTAL | J6: =SUM(J3:J5) -> 0
B8: LANÇAMENTOS DA FATURA | I8: ONDE ESTOU GASTANDO
B9: CARTÃO | C9: Data | D9: Descrição | E9: Parcela | F9: Categoria | G9: Valor | I9: Categoria | J9: Total | K9: %
I10: Mercado | J10: =SUMIF($F$10:$F$109,I10,$G$10:$G$109) -> 0 | K10: =IF($J$21=0,0,J10/$J$21) -> 0
I11: Restaurantes/Delivery | J11: =SUMIF($F$10:$F$109,I11,$G$10:$G$109) -> 0 | K11: =IF($J$21=0,0,J11/$J$21) -> 0
I12: Transporte/Combustível | J12: =SUMIF($F$10:$F$109,I12,$G$10:$G$109) -> 0 | K12: =IF($J$21=0,0,J12/$J$21) -> 0
I13: Assinaturas/Streaming | J13: =SUMIF($F$10:$F$109,I13,$G$10:$G$109) -> 0 | K13: =IF($J$21=0,0,J13/$J$21) -> 0
I14: Vestuário | J14: =SUMIF($F$10:$F$109,I14,$G$10:$G$109) -> 0 | K14: =IF($J$21=0,0,J14/$J$21) -> 0
I15: Saúde/Farmácia | J15: =SUMIF($F$10:$F$109,I15,$G$10:$G$109) -> 0 | K15: =IF($J$21=0,0,J15/$J$21) -> 0
I16: Casa | J16: =SUMIF($F$10:$F$109,I16,$G$10:$G$109) -> 0 | K16: =IF($J$21=0,0,J16/$J$21) -> 0
I17: Lazer | J17: =SUMIF($F$10:$F$109,I17,$G$10:$G$109) -> 0 | K17: =IF($J$21=0,0,J17/$J$21) -> 0
I18: Viagem | J18: =SUMIF($F$10:$F$109,I18,$G$10:$G$109) -> 0 | K18: =IF($J$21=0,0,J18/$J$21) -> 0
I19: Educação | J19: =SUMIF($F$10:$F$109,I19,$G$10:$G$109) -> 0 | K19: =IF($J$21=0,0,J19/$J$21) -> 0
I20: Outros | J20: =SUMIF($F$10:$F$109,I20,$G$10:$G$109) -> 0 | K20: =IF($J$21=0,0,J20/$J$21) -> 0
I21: Total | J21: =SUM(J10:J20) -> 0 | K21: =IF(J21=0,0,J21/J21) -> 0
B110: Total | C110: Total | G110: =SUM(G10:G109) -> 0

Sheet Julho
B1: CONTROLE MENSAL
B2: Mês: | C2: Julho
B4: Total de Entradas | C4: =C21 -> 10950.24 | G4: Total Pago | H4: =SUMIF($I$11:$I$60,"Pago",$H$11:$H$60) -> 4474.894
B5: Total de Saídas | C5: =L20 -> 9298.474 | G5: Total a Pagar | H5: =SUMIF($I$11:$I$60,"Não pago",$H$11:$H$60) -> 0
B6: Saldo do Mês | C6: =C4-C5 -> 1651.766
B9: ENTRADAS | E9: SAÍDAS (exceto cartão de crédito) | K9: RESUMO POR CATEGORIA
B10: Descrição | C10: Valor | E10: Data | F10: Descrição | G10: Categoria | H10: Valor | I10: Pago? | K10: Categoria | L10: Total | M10: %
B11: SALARIO | C11: 9650.24 | E11: 46209 | F11: DIZIMO | G11: Outros | H11: =C11*10% -> 965.024 | I11: Pago | K11: Moradia (aluguel/condomínio) | L11: =SUMIF($G$11:$G$60,K11,$H$11:$H$60) -> 1315.3 | M11: =IF($L$20=0,0,L11/$L$20) -> 0.14145332
B12: DIVIDENDO | C12: 1300 | E12: 46209 | F12: PARCELA MRV | G12: Moradia (aluguel/condomínio) | H12: 1276.48 | I12: Pago | K12: Contas (luz/água/internet) | L12: =SUMIF($G$11:$G$60,K12,$H$11:$H$60) -> 690.78 | M12: =IF($L$20=0,0,L12/$L$20) -> 0.074289609
E13: =E12 -> 46209 | F13: SEGURO MRV | G13: Moradia (aluguel/condomínio) | H13: 38.82 | I13: Pago | K13: Mercado | L13: =SUMIF($G$11:$G$60,K13,$H$11:$H$60) -> 0 | M13: =IF($L$20=0,0,L13/$L$20) -> 0
E14: =E13 -> 46209 | F14: APCEF | G14: Saúde | H14: 41 | I14: Pago | K14: Transporte | L14: =SUMIF($G$11:$G$60,K14,$H$11:$H$60) -> 0 | M14: =IF($L$20=0,0,L14/$L$20) -> 0
E15: 46210 | F15: ENERGIA | G15: Contas (luz/água/internet) | H15: 690.78 | I15: Pago | K15: Saúde | L15: =SUMIF($G$11:$G$60,K15,$H$11:$H$60) -> 794.53 | M15: =IF($L$20=0,0,L15/$L$20) -> 0.085447354
E16: 46213 | F16: PASSAPORTE | G16: Lazer | H16: 257.25 | I16: Pago | K16: Educação | L16: =SUMIF($G$11:$G$60,K16,$H$11:$H$60) -> 0 | M16: =IF($L$20=0,0,L16/$L$20) -> 0
E17: 46223 | F17: HUMANAS DENTINHO | G17: Saúde | H17: 8 | I17: Pago | K17: Lazer | L17: =SUMIF($G$11:$G$60,K17,$H$11:$H$60) -> 377.25 | M17: =IF($L$20=0,0,L17/$L$20) -> 0.040571173
E18: 46223 | F18: HUMANAS SAUDE | G18: Saúde | H18: 745.53 | I18: Pago | K18: Outros | L18: =SUMIF($G$11:$G$60,K18,$H$11:$H$60) -> 1297.034 | M18: =IF($L$20=0,0,L18/$L$20) -> 0.13948891
E19: 46223 | F19: NUBAK HELENA | G19: Outros | H19: 332.01 | I19: Pago | K19: Cartão de Crédito | L19: ='Julho-Cartão'!D4 -> 4823.58 | M19: =IF($L$20=0,0,L19/$L$20) -> 0.51874964
E20: 46218 | F20: CEA | G20: Lazer | H20: 120 | I20: Pago | K20: Total | L20: =SUM(L11:L19) -> 9298.474 | M20: =IF(L20=0,0,L20/L20) -> 1
B21: Total | C21: =SUM(C11:C20) -> 10950.24
K22: O Cartão de Crédito vem automático da aba "Mês-Cartão" — não lance a fatura nas Saídas.
E61: Total lançado | H61: =SUM(H11:H60) -> 4474.894

Sheet Julho-Cartão
B1: ESTUDO DA FATURA DO CARTÃO DE CRÉDITO
C2: Mês: | D2: Julho | E2: ← digite o mesmo nome da aba do mês (ex.: Janeiro)
I3: NU RICARDO | J3: =SUMIFS(G:G,B:B,I3) -> 807.48
C4: Total da Fatura | D4: =G110 -> 4823.58 | I4: VISA RICARDO | J4: =SUMIFS(G:G,B:B,I4) -> 4016.1
I5: NU HELENA | J5: =SUMIFS(G:G,B:B,I5) -> 0
I6: TOTAL | J6: =SUM(J3:J5) -> 4823.58
B8: LANÇAMENTOS DA FATURA | I8: ONDE ESTOU GASTANDO
B9: CARTÃO | C9: Data | D9: Descrição | E9: Parcela | F9: Categoria | G9: Valor | I9: Categoria | J9: Total | K9: %
B10: NU RICARDO | C10: 46178 | D10: Havan Sao Luiz | E10: 3/4 | F10: Casa | G10: 64.99 | I10: Mercado | J10: =SUMIF($F$10:$F$109,I10,$G$10:$G$109) -> 272.84 | K10: =IF($J$21=0,0,J10/$J$21) -> 0.056563797
B11: NU RICARDO | C11: 46178 | D11: Gol Linhas Aéreas | E11: 5/5 | F11: Viagem | G11: 104.06 | I11: Restaurantes/Delivery | J11: =SUMIF($F$10:$F$109,I11,$G$10:$G$109) -> 1709.51 | K11: =IF($J$21=0,0,J11/$J$21) -> 0.35440689
B12: NU RICARDO | C12: 46178 | D12: Riachuelo | E12: 3/3 | F12: Vestuário | G12: 106.65 | I12: Transporte/Combustível | J12: =SUMIF($F$10:$F$109,I12,$G$10:$G$109) -> 277.63 | K12: =IF($J$21=0,0,J12/$J$21) -> 0.057556835
B13: NU RICARDO | C13: 46178 | D13: Farmácias Pague Menos | E13: 5/5 | F13: Saúde/Farmácia | G13: 57.78 | I13: Assinaturas/Streaming | J13: =SUMIF($F$10:$F$109,I13,$G$10:$G$109) -> 118.45 | K13: =IF($J$21=0,0,J13/$J$21) -> 0.02455645
B14: NU RICARDO | C14: 46178 | D14: Vivara | E14: 8/10 | F14: Vestuário | G14: 474 | I14: Vestuário | J14: =SUMIF($F$10:$F$109,I14,$G$10:$G$109) -> 807.95 | K14: =IF($J$21=0,0,J14/$J$21) -> 0.16750007
B15: VISA RICARDO | C15: 46167 | D15: IFD*BR | F15: Restaurantes/Delivery | G15: -49.9 | I15: Saúde/Farmácia | J15: =SUMIF($F$10:$F$109,I15,$G$10:$G$109) -> 271.15 | K15: =IF($J$21=0,0,J15/$J$21) -> 0.056213435
B16: VISA RICARDO | C16: 46181 | D16: EMPORIO PINHEIRO | F16: Mercado | G16: 31.47 | I16: Casa | J16: =SUMIF($F$10:$F$109,I16,$G$10:$G$109) -> 227.92 | K16: =IF($J$21=0,0,J16/$J$21) -> 0.047251212
B17: VISA RICARDO | C17: 46181 | D17: EspetinDeRua | F17: Restaurantes/Delivery | G17: 25 | I17: Lazer | J17: =SUMIF($F$10:$F$109,I17,$G$10:$G$109) -> 136.1 | K17: =IF($J$21=0,0,J17/$J$21) -> 0.028215558
B18: VISA RICARDO | C18: 46182 | D18: EMPORIO PINHEIRO | F18: Mercado | G18: 73.35 | I18: Viagem | J18: =SUMIF($F$10:$F$109,I18,$G$10:$G$109) -> 153.76 | K18: =IF($J$21=0,0,J18/$J$21) -> 0.031876739
B19: VISA RICARDO | C19: 46183 | D19: VICKS BURGER ILHA | F19: Restaurantes/Delivery | G19: 49.9 | I19: Educação | J19: =SUMIF($F$10:$F$109,I19,$G$10:$G$109) -> 349.17 | K19: =IF($J$21=0,0,J19/$J$21) -> 0.072388143
B20: VISA RICARDO | C20: 46183 | D20: PAGUE MENOS 06 | F20: Saúde/Farmácia | G20: 19.5 | I20: Outros | J20: =SUMIF($F$10:$F$109,I20,$G$10:$G$109) -> 499.1 | K20: =IF($J$21=0,0,J20/$J$21) -> 0.10347087
B21: VISA RICARDO | C21: 46183 | D21: EspetinDeRua | F21: Restaurantes/Delivery | G21: 25 | I21: Total | J21: =SUM(J10:J20) -> 4823.58 | K21: =IF(J21=0,0,J21/J21) -> 1
B22: VISA RICARDO | C22: 46183 | D22: SHOPPING ILHA SA CAVAL | F22: Lazer | G22: 40.9
B23: VISA RICARDO | C23: 46184 | D23: EMPORIO PINHEIRO | F23: Mercado | G23: 18.03
B24: VISA RICARDO | C24: 46185 | D24: UBER * PENDING | F24: Transporte/Combustível | G24: 23.98
B25: VISA RICARDO | C25: 46185 | D25: EMPORIO PINHEIRO | F25: Mercado | G25: 14.18
B26: VISA RICARDO | C26: 46185 | D26: IFD*BR | F26: Restaurantes/Delivery | G26: 108.28
B27: VISA RICARDO | C27: 46186 | D27: DAISO | F27: Casa | G27: 67.96
B28: VISA RICARDO | C28: 46186 | D28: BRASIL CACAU | F28: Restaurantes/Delivery | G28: 42.98
B29: VISA RICARDO | C29: 46186 | D29: LE BISCUIT | F29: Casa | G29: 94.97
B30: VISA RICARDO | C30: 46186 | D30: SHOPPING DA ILHA | F30: Lazer | G30: 63.2
B31: VISA RICARDO | C31: 46186 | D31: OUTBACK SHOPPING AMERI | F31: Restaurantes/Delivery | G31: 263.98
B32: VISA RICARDO | C32: 46186 | D32: Estacionamento | F32: Transporte/Combustível | G32: 17
B33: VISA RICARDO | C33: 46188 | D33: EspetinDeRua | F33: Restaurantes/Delivery | G33: 50
... B56: VISA RICARDO | C56: 46199 | D56: MP*RAPHAEL | F56: Restaurantes/Delivery | G56: 23.18
B57: VISA RICARDO | C57: 46199 | D57: 42908470Adriano | E57: 01/03 | F57: Outros | G57: 137.98
B58: VISA RICARDO | C58: 46200 | D58: CAPPTA *R DE GOIS DALE | F58: Restaurantes/Delivery | G58: 45.98
B59: VISA RICARDO | C59: 46201 | D59: PARADA 163 | F59: Restaurantes/Delivery | G59: 58
B60: VISA RICARDO | C60: 46202 | D60: PARADA 163 | F60: Restaurantes/Delivery | G60: 24
B61: VISA RICARDO | C61: 46202 | D61: CAPPTA *GESSI VIEIRA D | F61: Restaurantes/Delivery | G61: 25.06
B62: VISA RICARDO | C62: 46203 | D62: CLARICES | F62: Restaurantes/Delivery | G62: 87.1
B63: VISA RICARDO | C63: 46203 | D63: CAPPTA *R DE GOIS DALE | F63: Restaurantes/Delivery | G63: 38.88
...

Sheet Agosto
B1: CONTROLE MENSAL
B2: Mês: | C2: Agosto
B4: Total de Entradas | C4: =C21 -> 17241.54 | G4: Total Pago | H4: =SUMIF($I$11:$I$60,"Pago",$H$11:$H$60) -> 0
B5: Total de Saídas | C5: =L20 -> 20477.424 | G5: Total a Pagar | H5: =SUMIF($I$11:$I$60,"Não pago",$H$11:$H$60) -> 20477.424
B6: Saldo do Mês | C6: =C4-C5 -> -3235.884
B9: ENTRADAS | E9: SAÍDAS | K9: RESUMO POR CATEGORIA
B10: Descrição | C10: Valor | E10: Data | F10: Descrição | G10: Categoria | H10: Valor | I10: Pago? | K10: Categoria | L10: Total | M10: %
B11: SALARIO | C11: 9650.24 | E11: 46240 | F11: DIZIMO | G11: Outros | H11: =C11*10% -> 965.024 | I11: Não pago | K11: Moradia (aluguel/condomínio) | L11: =SUMIF($G$11:$G$60,K11,$H$11:$H$60) -> 12918.91 | M11: =IF($L$20=0,0,L11/$L$20) -> 0.63088551
B12: RESGATE | C12: 7591.3 | K12: Contas (luz/água/internet) | L12: =SUMIF($G$11:$G$60,K12,$H$11:$H$60) -> 690.78 | M12: =IF($L$20=0,0,L12/$L$20) -> 0.033733735
E13: 46240 | F13: APCEF | G13: Saúde | H13: 41 | I13: Não pago | K13: Mercado | L13: =SUMIF($G$11:$G$60,K13,$H$11:$H$60) -> 320 | M13: =IF($L$20=0,0,L13/$L$20) -> 0.015626966
E14: 46254 | F14: HUMANAS DENTINHO | G14: Saúde | H14: 8 | I14: Não pago | K14: Transporte | L14: =SUMIF($G$11:$G$60,K14,$H$11:$H$60) -> 0 | M14: =IF($L$20=0,0,L14/$L$20) -> 0
E15: 46254 | F15: HUMANAS SAUDE | G15: Saúde | H15: 745.53 | I15: Não pago | K15: Saúde | L15: =SUMIF($G$11:$G$60,K15,$H$11:$H$60) -> 874.53 | M15: =IF($L$20=0,0,L15/$L$20) -> 0.042707032
K16: Educação | L16: =SUMIF($G$11:$G$60,K16,$H$11:$H$60) -> 0 | M16: =IF($L$20=0,0,L16/$L$20) -> 0
E17: 46243 | F17: PARCELA MRV | G17: Moradia (aluguel/condomínio) | H17: 1278.52 | I17: Não pago | K17: Lazer | L17: =SUMIF($G$11:$G$60,K17,$H$11:$H$60) -> 120 | M17: =IF($L$20=0,0,L17/$L$20) -> 0.0058601121
E18: 46243 | F18: SEGURO MRV | G18: Moradia (aluguel/condomínio) | H18: 38.59 | I18: Não pago | K18: Outros | L18: =SUMIF($G$11:$G$60,K18,$H$11:$H$60) -> 1265.024 | M18: =IF($L$20=0,0,L18/$L$20) -> 0.06177652
E19: 46243 | F19: MRV | G19: Moradia (aluguel/condomínio) | H19: 11601.8 | I19: Não pago | K19: Cartão de Crédito | L19: =SUMIF($G$11:$G$60,K19,$H$11:$H$60) -> 4288.18 | M19: =IF($L$20=0,0,L19/$L$20) -> 0.20941013
K20: Total | L20: =SUM(L11:L19) -> 20477.424 | M20: =IF(L20=0,0,L20/L20) -> 1
B21: Total | C21: =SUM(C11:C20) -> 17241.54
E22: 46241 | F22: ENERGIA | G22: Contas (luz/água/internet) | H22: 690.78 | I22: Não pago | K22: O Cartão de Crédito vem automático da aba "Mês-Cartão" — não lance a fatura nas Saídas.
E24: 46243 | F24: RICARDO NU BANK | G24: Cartão de Crédito | H24: 538.99 | I24: Não pago
E25: 46246 | F25: RICARDO VISA | G25: Cartão de Crédito | H25: ='Agosto-Cartão'!J4 -> 3549.19 | I25: Não pago | L25: =IFERROR('Agosto-Cartão'!D4,0) -> 3549.19
E26: 46254 | F26: NUBAK HELENA | G26: Cartão de Crédito | H26: 200 | I26: Não pago
E28: 46249 | F28: CEA | G28: Lazer | H28: 120 | I28: Não pago
E30: 46244 | F30: APLICAÇÃO AURORA | G30: Outros | H30: 300 | I30: Não pago
E31: 46263 | F31: SEGURO ITAU | G31: Saúde | H31: 80 | I31: Não pago
E33: 46241 | F33: ALIMENTAÇÃO LUCENA | G33: Mercado | H33: 320 | I33: Não pago
E61: Total lançado | H61: =SUM(H11:H60) -> 20477.424

Sheet Agosto-Cartão
B1: ESTUDO DA FATURA DO CARTÃO DE CRÉDITO
C2: Mês: | D2: Agosto | E2: ← digite o mesmo nome da aba do mês (ex.: Janeiro)
I3: NU RICARDO | J3: =SUMIFS(G:G,B:B,I3) -> 0
C4: Total da Fatura | D4: =G110 -> 3549.19 | I4: VISA RICARDO | J4: =SUMIFS(G:G,B:B,I4) -> 3549.19
I5: NU HELENA | J5: =SUMIFS(G:G,B:B,I5) -> 0
I6: TOTAL | J6: =SUM(J3:J5) -> 3549.19
B8: LANÇAMENTOS DA FATURA | I8: ONDE ESTOU GASTANDO
B9: CARTÃO | C9: Data | D9: Descrição | E9: Parcela | F9: Categoria | G9: Valor | I9: Categoria | J9: Total | K9: %
B10: VISA RICARDO | C10: 46216 | D10: 42908470Adriano | F10: Outros | G10: -0.04 | I10: Mercado | J10: =SUMIF($F$10:$F$109,I10,$G$10:$G$109) -> 263.63 | K10: =IF($J$21=0,0,J10/$J$21) -> 0.07427892
B11: VISA RICARDO | C11: 45955 | D11: CARROSSEL ACON | E11: 10/10 | F11: Outros | G11: 159.42 | I11: Restaurantes/Delivery | J11: =SUMIF($F$10:$F$109,I11,$G$10:$G$109) -> 1473.58 | K11: =IF($J$21=0,0,J11/$J$21) -> 0.41518769
B12: VISA RICARDO | C12: 45959 | D12: EXTRA FARMA -C | E12: 10/10 | F12: Saúde/Farmácia | G12: 143.5 | I12: Transporte/Combustível | J12: =SUMIF($F$10:$F$109,I12,$G$10:$G$109) -> 188.66 | K12: =IF($J$21=0,0,J12/$J$21) -> 0.05315579
B13: VISA RICARDO | C13: 46000 | D13: PG *GRAN LINKP | E13: 08/12 | F13: Educação | G13: 59.9 | I13: Assinaturas/Streaming | J13: =SUMIF($F$10:$F$109,I13,$G$10:$G$109) -> 98.55 | K13: =IF($J$21=0,0,J13/$J$21) -> 0.027766899
B14: VISA RICARDO | C14: 46008 | D14: HOTMART C3DDOZ | E14: 08/12 | F14: Educação | G14: 289.27 | I14: Vestuário | J14: =SUMIF($F$10:$F$109,I14,$G$10:$G$109) -> 128.48 | K14: =IF($J$21=0,0,J14/$J$21) -> 0.036199809
B15: VISA RICARDO | C15: 46073 | D15: AMAZON PRIME B | E15: 06/12 | F15: Assinaturas/Streaming | G15: 13.9 | I15: Saúde/Farmácia | J15: =SUMIF($F$10:$F$109,I15,$G$10:$G$109) -> 245.66 | K15: =IF($J$21=0,0,J15/$J$21) -> 0.069215793
B16: VISA RICARDO | C16: 46133 | D16: EBN*CANVA0485 | E16: 04/12 | F16: Assinaturas/Streaming | G16: 24.25 | I16: Casa | J16: =SUMIF($F$10:$F$109,I16,$G$10:$G$109) -> 8 | K16: =IF($J$21=0,0,J16/$J$21) -> 0.0022540354
B17: VISA RICARDO | C17: 46199 | D17: 42908470Adrian | E17: 02/03 | F17: Outros | G17: 137.98 | I17: Lazer | J17: =SUMIF($F$10:$F$109,I17,$G$10:$G$109) -> 96 | K17: =IF($J$21=0,0,J17/$J$21) -> 0.027048425
B18: VISA RICARDO | C18: 46206 | D18: Jbj | E18: 02/02 | F18: Vestuário | G18: 72.5 | I18: Viagem | J18: =SUMIF($F$10:$F$109,I18,$G$10:$G$109) -> 0 | K18: =IF($J$21=0,0,J18/$J$21) -> 0
B19: VISA RICARDO | C19: 46211 | D19: IFD*FNRN RESTAURANTE LT | F19: Restaurantes/Delivery | G19: 36.91 | I19: Educação | J19: =SUMIF($F$10:$F$109,I19,$G$10:$G$109) -> 459.07 | K19: =IF($J$21=0,0,J19/$J$21) -> 0.12934501
B20: VISA RICARDO | C20: 46211 | D20: EMPORIO PINHEIRO | F20: Mercado | G20: 12.98 | I20: Outros | J20: =SUMIF($F$10:$F$109,I20,$G$10:$G$109) -> 587.56 | K20: =IF($J$21=0,0,J20/$J$21) -> 0.16554763
B21: VISA RICARDO | C21: 46211 | D21: IFD*Leandro Da Silva | F21: Restaurantes/Delivery | G21: 2 | I21: Total | J21: =SUM(J10:J20) -> 3549.19 | K21: =IF(J21=0,0,J21/J21) -> 1
B22: VISA RICARDO | C22: 46212 | D22: SMARVIC COMERCIO E SE | F22: Outros | G22: 84.8
B23: VISA RICARDO | C23: 46212 | D23: SUBWAY HOLANDESES | F23: Restaurantes/Delivery | G23: 42
B24: VISA RICARDO | C24: 46212 | D24: EMPORIO PINHEIRO | F24: Mercado | G24: 20.06
B25: VISA RICARDO | C25: 46213 | D25: IFD*F P S RODRIGUES LT | F25: Restaurantes/Delivery | G25: 132.99
B26: VISA RICARDO | C26: 46213 | D26: EMPORIO PINHEIRO | F26: Mercado | G26: 18.88
B27: VISA RICARDO | C27: 46213 | D27: SDL - SAO LUIZ DANIEL | F27: Outros | G27: 88.9
B28: VISA RICARDO | C28: 46214 | D28: PRINCESA DOS SALGADOS | F28: Restaurantes/Delivery | G28: 26
B29: VISA RICARDO | C29: 46214 | D29: DIVERNO COHAJAP MAQUIN | F29: Lazer | G29: 96
B30: VISA RICARDO | C30: 46214 | D30: UBER * PENDING | F30: Transporte/Combustível | G30: 39.98
B31: VISA RICARDO | C31: 46215 | D31: PAGUE MENOS 084 | F31: Saúde/Farmácia | G31: 44.98
B32: VISA RICARDO | C32: 46215 | D32: A. B. COLINS LIMASAO JO | F32: Restaurantes/Delivery | G32: 83.8
B33: VISA RICARDO | C33: 46216 | D33: SUBWAY HOLANDESESSAO LU | F33: Restaurantes/Delivery | G33: 26.9
... B69: VISA RICARDO | C69: 46228 | D69: GB COMERCIO DE ALIMENTB | F69: Restaurantes/Delivery | G69: 61.6
B70: VISA RICARDO | C70: 46228 | D70: MP*MALUXBELEMB | E70: 01/12 | F70: Educação | G70: 109.9
B71: VISA RICARDO | C71: 46228 | D71: UBER * PENDINGSAO PAULO | F71: Transporte/Combustível | G71: 20.98
B72: VISA RICARDO | C72: 46228 | D72: PARSTOP ESTACIONAMENTSA | F72: Transporte/Combustível | G72: 7
B73: VISA RICARDO | C73: 46228 | D73: Mc Donalds - Arcos Dour | F73: Restaurantes/Delivery | G73: 118.9
B74: VISA RICARDO | C74: 46228 | D74: PbAdministradoraSAO LUI | F74: Outros | G74: 8
B75: VISA RICARDO | C75: 46229 | D75: A. B. COLINS LIMASAO JO | F75: Restaurantes/Delivery | G75: 85.9
B76: VISA RICARDO | C76: 46229 | D76: PARSTOP ESTACIONAMENTSA | F76: Transporte/Combustível | G76: 10
...

Sheet Setembro
B1: CONTROLE MENSAL
B2: Mês: | C2: Setembro | D2: ← digite aqui o mesmo nome da aba (ex.: Janeiro)
B4: Total de Entradas | C4: =C21 -> 0 | G4: Total Pago | H4: =SUMIF($I$11:$I$60,"Pago",$H$11:$H$60) -> 0
B5: Total de Saídas | C5: =L20 -> 0 | G5: Total a Pagar | H5: =SUMIF($I$11:$I$60,"Não pago",$H$11:$H$60) -> 0
B6: Saldo do Mês | C6: =C4-C5 -> 0
B9: ENTRADAS | E9: SAÍDAS (exceto cartão de crédito) | K9: RESUMO POR CATEGORIA
B10: Descrição | C10: Valor | E10: Data | F10: Descrição | G10: Categoria | H10: Valor | I10: Pago? | K10: Categoria | L10: Total | M10: %
K11: Moradia (aluguel/condomínio) | L11: =SUMIF($G$11:$G$60,K11,$H$11:$H$60) -> 0 | M11: =IF($L$20=0,0,L11/$L$20) -> 0
K12: Contas (luz/água/internet) | L12: =SUMIF($G$11:$G$60,K12,$H$11:$H$60) -> 0 | M12: =IF($L$20=0,0,L12/$L$20) -> 0
K13: Mercado | L13: =SUMIF($G$11:$G$60,K13,$H$11:$H$60) -> 0 | M13: =IF($L$20=0,0,L13/$L$20) -> 0
K14: Transporte | L14: =SUMIF($G$11:$G$60,K14,$H$11:$H$60) -> 0 | M14: =IF($L$20=0,0,L14/$L$20) -> 0
K15: Saúde | L15: =SUMIF($G$11:$G$60,K15,$H$11:$H$60) -> 0 | M15: =IF($L$20=0,0,L15/$L$20) -> 0
K16: Educação | L16: =SUMIF($G$11:$G$60,K16,$H$11:$H$60) -> 0 | M16: =IF($L$20=0,0,L16/$L$20) -> 0
K17: Lazer | L17: =SUMIF($G$11:$G$60,K17,$H$11:$H$60) -> 0 | M17: =IF($L$20=0,0,L17/$L$20) -> 0
K18: Outros | L18: =SUMIF($G$11:$G$60,K18,$H$11:$H$60) -> 0 | M18: =IF($L$20=0,0,L18/$L$20) -> 0
K19: Cartão de Crédito | L19: =IFERROR('Setembro-Cartão'!D4,0) -> 0 | M19: =IF($L$20=0,0,L19/$L$20) -> 0
K20: Total | L20: =SUM(L11:L19) -> 0 | M20: =IF(L20=0,0,L20/L20) -> 0
B21: Total | C21: =SUM(C11:C20) -> 0
K22: O Cartão de Crédito vem automático da aba "Mês-Cartão" — não lance a fatura nas Saídas.
E61: Total lançado | H61: =SUM(H11:H60) -> 0

Sheet Setembro-Cartão
B1: ESTUDO DA FATURA DO CARTÃO DE CRÉDITO
C2: Mês: | D2: Setembro | E2: ← digite o mesmo nome da aba do mês (ex.: Janeiro)
I3: NU RICARDO | J3: =SUMIFS(G:G,B:B,I3) -> 0
C4: Total da Fatura | D4: =G110 -> 0 | I4: VISA RICARDO | J4: =SUMIFS(G:G,B:B,I4) -> 0
I5: NU HELENA | J5: =SUMIFS(G:G,B:B,I5) -> 0
I6: TOTAL | J6: =SUM(J3:J5) -> 0
B8: LANÇAMENTOS DA FATURA | I8: ONDE ESTOU GASTANDO
B9: CARTÃO | C9: Data | D9: Descrição | E9: Parcela | F9: Categoria | G9: Valor | I9: Categoria | J9: Total | K9: %
I10: Mercado | J10: =SUMIF($F$10:$F$109,I10,$G$10:$G$109) -> 0 | K10: =IF($J$21=0,0,J10/$J$21) -> 0
I11: Restaurantes/Delivery | J11: =SUMIF($F$10:$F$109,I11,$G$10:$G$109) -> 0 | K11: =IF($J$21=0,0,J11/$J$21) -> 0
I12: Transporte/Combustível | J12: =SUMIF($F$10:$F$109,I12,$G$10:$G$109) -> 0 | K12: =IF($J$21=0,0,J12/$J$21) -> 0
I13: Assinaturas/Streaming | J13: =SUMIF($F$10:$F$109,I13,$G$10:$G$109) -> 0 | K13: =IF($J$21=0,0,J13/$J$21) -> 0
I14: Vestuário | J14: =SUMIF($F$10:$F$109,I14,$G$10:$G$109) -> 0 | K14: =IF($J$21=0,0,J14/$J$21) -> 0
I15: Saúde/Farmácia | J15: =SUMIF($F$10:$F$109,I15,$G$10:$G$109) -> 0 | K15: =IF($J$21=0,0,J15/$J$21) -> 0
I16: Casa | J16: =SUMIF($F$10:$F$109,I16,$G$10:$G$109) -> 0 | K16: =IF($J$21=0,0,J16/$J$21) -> 0
I17: Lazer | J17: =SUMIF($F$10:$F$109,I17,$G$10:$G$109) -> 0 | K17: =IF($J$21=0,0,J17/$J$21) -> 0
I18: Viagem | J18: =SUMIF($F$10:$F$109,I18,$G$10:$G$109) -> 0 | K18: =IF($J$21=0,0,J18/$J$21) -> 0
I19: Educação | J19: =SUMIF($F$10:$F$109,I19,$G$10:$G$109) -> 0 | K19: =IF($J$21=0,0,J19/$J$21) -> 0
I20: Outros | J20: =SUMIF($F$10:$F$109,I20,$G$10:$G$109) -> 0 | K20: =IF($J$21=0,0,J20/$J$21) -> 0
I21: Total | J21: =SUM(J10:J20) -> 0 | K21: =IF(J21=0,0,J21/J21) -> 0
B110: Total | C110: Total | G110: =SUM(G10:G109) -> 0

Sheet Outubro
B1: CONTROLE MENSAL
B2: Mês: | C2: Outubro | D2: ← digite aqui o mesmo nome da aba (ex.: Janeiro)
B4: Total de Entradas | C4: =C21 -> 0 | G4: Total Pago | H4: =SUMIF($I$11:$I$60,"Pago",$H$11:$H$60) -> 0
B5: Total de Saídas | C5: =L20 -> 0 | G5: Total a Pagar | H5: =SUMIF($I$11:$I$60,"Não pago",$H$11:$H$60) -> 0
B6: Saldo do Mês | C6: =C4-C5 -> 0
B9: ENTRADAS | E9: SAÍDAS (exceto cartão de crédito) | K9: RESUMO POR CATEGORIA
B10: Descrição | C10: Valor | E10: Data | F10: Descrição | G10: Categoria | H10: Valor | I10: Pago? | K10: Categoria | L10: Total | M10: %
K11: Moradia (aluguel/condomínio) | L11: =SUMIF($G$11:$G$60,K11,$H$11:$H$60) -> 0 | M11: =IF($L$20=0,0,L11/$L$20) -> 0
K12: Contas (luz/água/internet) | L12: =SUMIF($G$11:$G$60,K12,$H$11:$H$60) -> 0 | M12: =IF($L$20=0,0,L12/$L$20) -> 0
K13: Mercado | L13: =SUMIF($G$11:$G$60,K13,$H$11:$H$60) -> 0 | M13: =IF($L$20=0,0,L13/$L$20) -> 0
K14: Transporte | L14: =SUMIF($G$11:$G$60,K14,$H$11:$H$60) -> 0 | M14: =IF($L$20=0,0,L14/$L$20) -> 0
K15: Saúde | L15: =SUMIF($G$11:$G$60,K15,$H$11:$H$60) -> 0 | M15: =IF($L$20=0,0,L15/$L$20) -> 0
K16: Educação | L16: =SUMIF($G$11:$G$60,K16,$H$11:$H$60) -> 0 | M16: =IF($L$20=0,0,L16/$L$20) -> 0
K17: Lazer | L17: =SUMIF($G$11:$G$60,K17,$H$11:$H$60) -> 0 | M17: =IF($L$20=0,0,L17/$L$20) -> 0
K18: Outros | L18: =SUMIF($G$11:$G$60,K18,$H$11:$H$60) -> 0 | M18: =IF($L$20=0,0,L18/$L$20) -> 0
K19: Cartão de Crédito | L19: =IFERROR('Outubro-Cartão'!D4,0) -> 0 | M19: =IF($L$20=0,0,L19/$L$20) -> 0
K20: Total | L20: =SUM(L11:L19) -> 0 | M20: =IF(L20=0,0,L20/L20) -> 0
B21: Total | C21: =SUM(C11:C20) -> 0
K22: O Cartão de Crédito vem automático da aba "Mês-Cartão" — não lance a fatura nas Saídas.
E61: Total lançado | H61: =SUM(H11:H60) -> 0

Sheet Outubro-Cartão
B1: ESTUDO DA FATURA DO CARTÃO DE CRÉDITO
C2: Mês: | D2: Outubro | E2: ← digite o mesmo nome da aba do mês (ex.: Janeiro)
I3: NU RICARDO | J3: =SUMIFS(G:G,B:B,I3) -> 0
C4: Total da Fatura | D4: =G110 -> 0 | I4: VISA RICARDO | J4: =SUMIFS(G:G,B:B,I4) -> 0
I5: NU HELENA | J5: =SUMIFS(G:G,B:B,I5) -> 0
I6: TOTAL | J6: =SUM(J3:J5) -> 0
B8: LANÇAMENTOS DA FATURA | I8: ONDE ESTOU GASTANDO
B9: CARTÃO | C9: Data | D9: Descrição | E9: Parcela | F9: Categoria | G9: Valor | I9: Categoria | J9: Total | K9: %
I10: Mercado | J10: =SUMIF($F$10:$F$109,I10,$G$10:$G$109) -> 0 | K10: =IF($J$21=0,0,J10/$J$21) -> 0
I11: Restaurantes/Delivery | J11: =SUMIF($F$10:$F$109,I11,$G$10:$G$109) -> 0 | K11: =IF($J$21=0,0,J11/$J$21) -> 0
I12: Transporte/Combustível | J12: =SUMIF($F$10:$F$109,I12,$G$10:$G$109) -> 0 | K12: =IF($J$21=0,0,J12/$J$21) -> 0
I13: Assinaturas/Streaming | J13: =SUMIF($F$10:$F$109,I13,$G$10:$G$109) -> 0 | K13: =IF($J$21=0,0,J13/$J$21) -> 0
I14: Vestuário | J14: =SUMIF($F$10:$F$109,I14,$G$10:$G$109) -> 0 | K14: =IF($J$21=0,0,J14/$J$21) -> 0
I15: Saúde/Farmácia | J15: =SUMIF($F$10:$F$109,I15,$G$10:$G$109) -> 0 | K15: =IF($J$21=0,0,J15/$J$21) -> 0
I16: Casa | J16: =SUMIF($F$10:$F$109,I16,$G$10:$G$109) -> 0 | K16: =IF($J$21=0,0,J16/$J$21) -> 0
I17: Lazer | J17: =SUMIF($F$10:$F$109,I17,$G$10:$G$109) -> 0 | K17: =IF($J$21=0,0,J17/$J$21) -> 0
I18: Viagem | J18: =SUMIF($F$10:$F$109,I18,$G$10:$G$109) -> 0 | K18: =IF($J$21=0,0,J18/$J$21) -> 0
I19: Educação | J19: =SUMIF($F$10:$F$109,I19,$G$10:$G$109) -> 0 | K19: =IF($J$21=0,0,J19/$J$21) -> 0
I20: Outros | J20: =SUMIF($F$10:$F$109,I20,$G$10:$G$109) -> 0 | K20: =IF($J$21=0,0,J20/$J$21) -> 0
I21: Total | J21: =SUM(J10:J20) -> 0 | K21: =IF(J21=0,0,J21/J21) -> 0
B110: Total | C110: Total | G110: =SUM(G10:G109) -> 0

Sheet Novembro
B1: CONTROLE MENSAL
B2: Mês: | C2: Novembro | D2: ← digite aqui o mesmo nome da aba (ex.: Janeiro)
B4: Total de Entradas | C4: =C21 -> 0 | G4: Total Pago | H4: =SUMIF($I$11:$I$60,"Pago",$H$11:$H$60) -> 0
B5: Total de Saídas | C5: =L20 -> 0 | G5: Total a Pagar | H5: =SUMIF($I$11:$I$60,"Não pago",$H$11:$H$60) -> 0
B6: Saldo do Mês | C6: =C4-C5 -> 0
B9: ENTRADAS | E9: SAÍDAS (exceto cartão de crédito) | K9: RESUMO POR CATEGORIA
B10: Descrição | C10: Valor | E10: Data | F10: Descrição | G10: Categoria | H10: Valor | I10: Pago? | K10: Categoria | L10: Total | M10: %
K11: Moradia (aluguel/condomínio) | L11: =SUMIF($G$11:$G$60,K11,$H$11:$H$60) -> 0 | M11: =IF($L$20=0,0,L11/$L$20) -> 0
K12: Contas (luz/água/internet) | L12: =SUMIF($G$11:$G$60,K12,$H$11:$H$60) -> 0 | M12: =IF($L$20=0,0,L12/$L$20) -> 0
K13: Mercado | L13: =SUMIF($G$11:$G$60,K13,$H$11:$H$60) -> 0 | M13: =IF($L$20=0,0,L13/$L$20) -> 0
K14: Transporte | L14: =SUMIF($G$11:$G$60,K14,$H$11:$H$60) -> 0 | M14: =IF($L$20=0,0,L14/$L$20) -> 0
K15: Saúde | L15: =SUMIF($G$11:$G$60,K15,$H$11:$H$60) -> 0 | M15: =IF($L$20=0,0,L15/$L$20) -> 0
K16: Educação | L16: =SUMIF($G$11:$G$60,K16,$H$11:$H$60) -> 0 | M16: =IF($L$20=0,0,L16/$L$20) -> 0
K17: Lazer | L17: =SUMIF($G$11:$G$60,K17,$H$11:$H$60) -> 0 | M17: =IF($L$20=0,0,L17/$L$20) -> 0
K18: Outros | L18: =SUMIF($G$11:$G$60,K18,$H$11:$H$60) -> 0 | M18: =IF($L$20=0,0,L18/$L$20) -> 0
K19: Cartão de Crédito | L19: =IFERROR('Novembro-Cartão'!D4,0) -> 0 | M19: =IF($L$20=0,0,L19/$L$20) -> 0
K20: Total | L20: =SUM(L11:L19) -> 0 | M20: =IF(L20=0,0,L20/L20) -> 0
B21: Total | C21: =SUM(C11:C20) -> 0
K22: O Cartão de Crédito vem automático da aba "Mês-Cartão" — não lance a fatura nas Saídas.
E61: Total lançado | H61: =SUM(H11:H60) -> 0

Sheet Novembro-Cartão
B1: ESTUDO DA FATURA DO CARTÃO DE CRÉDITO
C2: Mês: | D2: Novembro | E2: ← digite o mesmo nome da aba do mês (ex.: Janeiro)
I3: NU RICARDO | J3: =SUMIFS(G:G,B:B,I3) -> 0
C4: Total da Fatura | D4: =G110 -> 0 | I4: VISA RICARDO | J4: =SUMIFS(G:G,B:B,I4) -> 0
I5: NU HELENA | J5: =SUMIFS(G:G,B:B,I5) -> 0
I6: TOTAL | J6: =SUM(J3:J5) -> 0
B8: LANÇAMENTOS DA FATURA | I8: ONDE ESTOU GASTANDO
B9: CARTÃO | C9: Data | D9: Descrição | E9: Parcela | F9: Categoria | G9: Valor | I9: Categoria | J9: Total | K9: %
I10: Mercado | J10: =SUMIF($F$10:$F$109,I10,$G$10:$G$109) -> 0 | K10: =IF($J$21=0,0,J10/$J$21) -> 0
I11: Restaurantes/Delivery | J11: =SUMIF($F$10:$F$109,I11,$G$10:$G$109) -> 0 | K11: =IF($J$21=0,0,J11/$J$21) -> 0
I12: Transporte/Combustível | J12: =SUMIF($F$10:$F$109,I12,$G$10:$G$109) -> 0 | K12: =IF($J$21=0,0,J12/$J$21) -> 0
I13: Assinaturas/Streaming | J13: =SUMIF($F$10:$F$109,I13,$G$10:$G$109) -> 0 | K13: =IF($J$21=0,0,J13/$J$21) -> 0
I14: Vestuário | J14: =SUMIF($F$10:$F$109,I14,$G$10:$G$109) -> 0 | K14: =IF($J$21=0,0,J14/$J$21) -> 0
I15: Saúde/Farmácia | J15: =SUMIF($F$10:$F$109,I15,$G$10:$G$109) -> 0 | K15: =IF($J$21=0,0,J15/$J$21) -> 0
I16: Casa | J16: =SUMIF($F$10:$F$109,I16,$G$10:$G$109) -> 0 | K16: =IF($J$21=0,0,J16/$J$21) -> 0
I17: Lazer | J17: =SUMIF($F$10:$F$109,I17,$G$10:$G$109) -> 0 | K17: =IF($J$21=0,0,J17/$J$21) -> 0
I18: Viagem | J18: =SUMIF($F$10:$F$109,I18,$G$10:$G$109) -> 0 | K18: =IF($J$21=0,0,J18/$J$21) -> 0
I19: Educação | J19: =SUMIF($F$10:$F$109,I19,$G$10:$G$109) -> 0 | K19: =IF($J$21=0,0,J19/$J$21) -> 0
I20: Outros | J20: =SUMIF($F$10:$F$109,I20,$G$10:$G$109) -> 0 | K20: =IF($J$21=0,0,J20/$J$21) -> 0
I21: Total | J21: =SUM(J10:J20) -> 0 | K21: =IF(J21=0,0,J21/J21) -> 0
B110: Total | C110: Total | G110: =SUM(G10:G109) -> 0

Sheet Dezembro
B1: CONTROLE MENSAL
B2: Mês: | C2: Dezembro | D2: ← digite aqui o mesmo nome da aba (ex.: Janeiro)
B4: Total de Entradas | C4: =C21 -> 0 | G4: Total Pago | H4: =SUMIF($I$11:$I$60,"Pago",$H$11:$H$60) -> 0
B5: Total de Saídas | C5: =L20 -> 0 | G5: Total a Pagar | H5: =SUMIF($I$11:$I$60,"Não pago",$H$11:$H$60) -> 0
B6: Saldo do Mês | C6: =C4-C5 -> 0
B9: ENTRADAS | E9: SAÍDAS (exceto cartão de crédito) | K9: RESUMO POR CATEGORIA
B10: Descrição | C10: Valor | E10: Data | F10: Descrição | G10: Categoria | H10: Valor | I10: Pago? | K10: Categoria | L10: Total | M10: %
K11: Moradia (aluguel/condomínio) | L11: =SUMIF($G$11:$G$60,K11,$H$11:$H$60) -> 0 | M11: =IF($L$20=0,0,L11/$L$20) -> 0
K12: Contas (luz/água/internet) | L12: =SUMIF($G$11:$G$60,K12,$H$11:$H$60) -> 0 | M12: =IF($L$20=0,0,L12/$L$20) -> 0
K13: Mercado | L13: =SUMIF($G$11:$G$60,K13,$H$11:$H$60) -> 0 | M13: =IF($L$20=0,0,L13/$L$20) -> 0
K14: Transporte | L14: =SUMIF($G$11:$G$60,K14,$H$11:$H$60) -> 0 | M14: =IF($L$20=0,0,L14/$L$20) -> 0
K15: Saúde | L15: =SUMIF($G$11:$G$60,K15,$H$11:$H$60) -> 0 | M15: =IF($L$20=0,0,L15/$L$20) -> 0
K16: Educação | L16: =SUMIF($G$11:$G$60,K16,$H$11:$H$60) -> 0 | M16: =IF($L$20=0,0,L16/$L$20) -> 0
K17: Lazer | L17: =SUMIF($G$11:$G$60,K17,$H$11:$H$60) -> 0 | M17: =IF($L$20=0,0,L17/$L$20) -> 0
K18: Outros | L18: =SUMIF($G$11:$G$60,K18,$H$11:$H$60) -> 0 | M18: =IF($L$20=0,0,L18/$L$20) -> 0
K19: Cartão de Crédito | L19: =IFERROR('Dezembro-Cartão'!D4,0) -> 0 | M19: =IF($L$20=0,0,L19/$L$20) -> 0
K20: Total | L20: =SUM(L11:L19) -> 0 | M20: =IF(L20=0,0,L20/L20) -> 0
B21: Total | C21: =SUM(C11:C20) -> 0
K22: O Cartão de Crédito vem automático da aba "Mês-Cartão" — não lance a fatura nas Saídas.
E61: Total lançado | H61: =SUM(H11:H60) -> 0

Sheet Dezembro-Cartão
B1: ESTUDO DA FATURA DO CARTÃO DE CRÉDITO
C2: Mês: | D2: Dezembro | E2: ← digite o mesmo nome da aba do mês (ex.: Janeiro)
I3: NU RICARDO | J3: =SUMIFS(G:G,B:B,I3) -> 0
C4: Total da Fatura | D4: =G110 -> 0 | I4: VISA RICARDO | J4: =SUMIFS(G:G,B:B,I4) -> 0
I5: NU HELENA | J5: =SUMIFS(G:G,B:B,I5) -> 0
I6: TOTAL | J6: =SUM(J3:J5) -> 0
B8: LANÇAMENTOS DA FATURA | I8: ONDE ESTOU GASTANDO
B9: CARTÃO | C9: Data | D9: Descrição | E9: Parcela | F9: Categoria | G9: Valor | I9: Categoria | J9: Total | K9: %
I10: Mercado | J10: =SUMIF($F$10:$F$109,I10,$G$10:$G$109) -> 0 | K10: =IF($J$21=0,0,J10/$J$21) -> 0
I11: Restaurantes/Delivery | J11: =SUMIF($F$10:$F$109,I11,$G$10:$G$109) -> 0 | K11: =IF($J$21=0,0,J11/$J$21) -> 0
I12: Transporte/Combustível | J12: =SUMIF($F$10:$F$109,I12,$G$10:$G$109) -> 0 | K12: =IF($J$21=0,0,J12/$J$21) -> 0
I13: Assinaturas/Streaming | J13: =SUMIF($F$10:$F$109,I13,$G$10:$G$109) -> 0 | K13: =IF($J$21=0,0,J13/$J$21) -> 0
I14: Vestuário | J14: =SUMIF($F$10:$F$109,I14,$G$10:$G$109) -> 0 | K14: =IF($J$21=0,0,J14/$J$21) -> 0
I15: Saúde/Farmácia | J15: =SUMIF($F$10:$F$109,I15,$G$10:$G$109) -> 0 | K15: =IF($J$21=0,0,J15/$J$21) -> 0
I16: Casa | J16: =SUMIF($F$10:$F$109,I16,$G$10:$G$109) -> 0 | K16: =IF($J$21=0,0,J16/$J$21) -> 0
I17: Lazer | J17: =SUMIF($F$10:$F$109,I17,$G$10:$G$109) -> 0 | K17: =IF($J$21=0,0,J17/$J$21) -> 0
I18: Viagem | J18: =SUMIF($F$10:$F$109,I18,$G$10:$G$109) -> 0 | K18: =IF($J$21=0,0,J18/$J$21) -> 0
I19: Educação | J19: =SUMIF($F$10:$F$109,I19,$G$10:$G$109) -> 0 | K19: =IF($J$21=0,0,J19/$J$21) -> 0
I20: Outros | J20: =SUMIF($F$10:$F$109,I20,$G$10:$G$109) -> 0 | K20: =IF($J$21=0,0,J20/$J$21) -> 0
I21: Total | J21: =SUM(J10:J20) -> 0 | K21: =IF(J21=0,0,J21/J21) -> 0
B110: Total | C110: Total | G110: =SUM(G10:G109) -> 0
